Workbook

Sheet Dashboard
A1: 💰 FINANZAS PERSONALES
A3: CONFIGURACIÓN | D3: RESUMEN
A4: Jornal mensual (€) | B4: 2375 | D4: Total gastos | E4: =Gastos!C39 -> 1518.5
A5: Mes | B5: 46174 | D5: Total inversión | E5: =Gastos!C40 -> 400
D6: Ahorros (libre) | E6: =Gastos!C42 -> 456.5
D7: % gastado | E7: =IF(Dashboard!B4=0,0,Gastos!C39/Dashboard!B4) -> 0.63936842
D8: % inversión | E8: =IF(Dashboard!B4=0,0,Gastos!C40/Dashboard!B4) -> 0.16842105
D9: % ahorros | E9: =IF(Dashboard!B4=0,0,Gastos!C42/Dashboard!B4) -> 0.19221053
A11: DESGLOSE POR CATEGORÍA
A12: Categoría | B12: % Jornal | D12: € Mensual
A13: 🏠 Casa (bote común) | B13: =Gastos!B13 -> 0.34 | D13: =Gastos!C13 -> 800
A14: 📋 Cuota autónomo | B14: =Gastos!B15 -> 0.18 | D14: =Gastos!C15 -> 427.5
A15: 🎭 Ocio | B15: =Gastos!B17 -> 0.08 | D15: =Gastos!C17 -> 200
A16: 🏋️ Gym | B16: =Gastos!B19 -> 0.01 | D16: =Gastos!C19 -> 25
A17: 📈 Fondos inversión | B17: =Gastos!B21 -> 0.08 | D17: =Gastos!C21 -> 200
A18: 🏦 Plan pensiones | B18: =Gastos!B22 -> 0.08 | D18: =Gastos!C22 -> 200
A19: 👕 Ropa | B19: =Gastos!B25 -> 0.01 | D19: =Gastos!C25 -> 15
A20: 🎁 Regalos | B20: =Gastos!B27 -> 0.01 | D20: =Gastos!C27 -> 15
A21: 🧴 Higiene | B21: =Gastos!B29 -> 0 | D21: =Gastos!C29 -> 0
A22: 🍔 Alimentación extra | B22: =Gastos!B31 -> 0 | D22: =Gastos!C31 -> 0
A23: 💊 Salud | B23: =Gastos!B33 -> 0.01 | D23: =Gastos!C33 -> 33
A24: 📱 Suscripciones | B24: =Gastos!B35 -> 0 | D24: =Gastos!C35 -> 3
A25: 🎓 Formación | B25: =Gastos!B37 -> 0 | D25: =Gastos!C37 -> 0
A26: 💰 Ahorros (libre) | B26: =Gastos!B42 -> 0.19221053 | D26: =Gastos!C42 -> 456.5
A27: TOTAL | B27: =Gastos!B41+Gastos!B42 -> 0.99221053 | D27: =Dashboard!B4 -> 2375

Sheet Gastos
A1: GASTOS MENSUALES
A2: Jornal | B2: =Dashboard!B4 -> 2375 | D2: ← Desde Dashboard
A3: CASA
A4: Alquiler / hipoteca | B4: 0.34 | C4: 800 | D4: Tu parte
A5: Mantenimiento coche | B5: 0 | C5: 0 | D5: Seguro, ITV, revisiones
A6: Viajes | B6: 0 | C6: 0 | D6: Transporte, escapadas
A7: Luz | B7: 0 | C7: 0
A8: Agua | B8: 0 | C8: 0
A9: Gasolina | B9: 0 | C9: 0
A10: Mascota | B10: 0 | C10: 0 | D10: Comida, vet, accesorios
A11: Supermercado | B11: 0 | C11: 0 | D11: Tu parte de la compra
A12: Internet / móvil | B12: 0 | C12: 0 | D12: Fibra, tarifa móvil
A13: SUBTOTAL CASA | B13: =SUM(B4:B12) -> 0.34 | C13: =SUM(C4:C12) -> 800
A14: CUOTA AUTÓNOMO
A15: Cuota autónomo | B15: 0.18 | C15: 427.5 | D15: Seguridad Social
A16: OCIO
A17: Ocio & entretenimiento | B17: 0.08 | C17: 200 | D17: Salidas, cenas, actividades
A18: GYM
A19: Cuota gym / deporte | B19: 0.01 | C19: 25
A20: INVERSIONES
A21: Fondos de inversión | B21: 0.08 | C21: 200 | D21: Aportación mensual
A22: Plan de pensiones | B22: 0.08 | C22: 200 | D22: Límite 1.500€/año IRPF
A23: SUBTOTAL INVERSIONES | B23: =SUM(B21:B22) -> 0.16 | C23: =SUM(C21:C22) -> 400
A24: ROPA
A25: Ropa & calzado | B25: 0.01 | C25: 15
A26: REGALOS
A27: Regalos | B27: 0.01 | C27: 15 | D27: Cumpleaños, navidades...
A28: HIGIENE & CUIDADO
A29: Higiene, cosmética | B29: 0 | C29: 0
A30: ALIMENTACIÓN EXTRA
A31: Cafés, delivery, restaurantes | B31: 0 | C31: 0
A32: SALUD
A33: Seguro médico / farmacia | B33: 0.01 | C33: 33
A34: SUSCRIPCIONES
A35: Streaming, apps | B35: 0 | C35: 3 | D35: Netflix, Spotify, iCloud...
A36: FORMACIÓN
A37: Cursos, libros | B37: 0 | C37: 0
A39: TOTAL GASTOS | B39: =B13+B15+B17+B19+B25+B27+B29+B31+B33+B35+B37 -> 0.64 | C39: =C13+C15+C17+C19+C25+C27+C29+C31+C33+C35+C37 -> 1518.5
A40: TOTAL INVERSIÓN | B40: =B23 -> 0.16 | C40: =C23 -> 400
A41: TOTAL SALIDA | B41: =B39+B40 -> 0.8 | C41: =C39+C40 -> 1918.5
...

Sheet Histórico
A1: HISTÓRICO MENSUAL
A2: Categoría | B2: Ene | C2: Feb | D2: Mar | E2: Abr | F2: May | G2: Jun | H2: Jul | I2: Ago | J2: Sep | K2: Oct | L2: Nov | M2: Dic
A3: Casa (bote común) | B3: 0 | C3: 0 | D3: 0 | E3: 0 | F3: 800 | G3: 0 | H3: 0 | I3: 0 | J3: 0 | K3: 0 | L3: 0 | M3: 0
A4: Cuota autónomo | B4: 0 | C4: 0 | D4: 0 | E4: 0 | F4: 427.5 | G4: 0 | H4: 0 | I4: 0 | J4: 0 | K4: 0 | L4: 0 | M4: 0
A5: Ocio | B5: 0 | C5: 0 | D5: 0 | E5: 0 | F5: 200 | G5: 0 | H5: 0 | I5: 0 | J5: 0 | K5: 0 | L5: 0 | M5: 0
A6: Gym | B6: 0 | C6: 0 | D6: 0 | E6: 0 | F6: 25 | G6: 0 | H6: 0 | I6: 0 | J6: 0 | K6: 0 | L6: 0 | M6: 0
A7: Fondos inversión | B7: 0 | C7: 0 | D7: 0 | E7: 0 | F7: 200 | G7: 0 | H7: 0 | I7: 0 | J7: 0 | K7: 0 | L7: 0 | M7: 0
A8: Plan pensiones | B8: 0 | C8: 0 | D8: 0 | E8: 0 | F8: 200 | G8: 0 | H8: 0 | I8: 0 | J8: 0 | K8: 0 | L8: 0 | M8: 0
A9: Ropa | B9: 0 | C9: 0 | D9: 0 | E9: 0 | F9: 15 | G9: 0 | H9: 0 | I9: 0 | J9: 0 | K9: 0 | L9: 0 | M9: 0
A10: Regalos | B10: 0 | C10: 0 | D10: 0 | E10: 0 | F10: 15 | G10: 0 | H10: 0 | I10: 0 | J10: 0 | K10: 0 | L10: 0 | M10: 0
A11: Higiene | B11: 0 | C11: 0 | D11: 0 | E11: 0 | F11: 0 | G11: 0 | H11: 0 | I11: 0 | J11: 0 | K11: 0 | L11: 0 | M11: 0
A12: Alimentación extra | B12: 0 | C12: 0 | D12: 0 | E12: 0 | F12: 0 | G12: 0 | H12: 0 | I12: 0 | J12: 0 | K12: 0 | L12: 0 | M12: 0
A13: Salud | B13: 0 | C13: 0 | D13: 0 | E13: 0 | F13: 33 | G13: 0 | H13: 0 | I13: 0 | J13: 0 | K13: 0 | L13: 0 | M13: 0
A14: Suscripciones | B14: 0 | C14: 0 | D14: 0 | E14: 0 | F14: 3 | G14: 0 | H14: 0 | I14: 0 | J14: 0 | K14: 0 | L14: 0 | M14: 0
A15: Formación | B15: 0 | C15: 0 | D15: 0 | E15: 0 | F15: 0 | G15: 0 | H15: 0 | I15: 0 | J15: 0 | K15: 0 | L15: 0 | M15: 0 | N15: TOTAL AHORRO
A16: Ahorros | B16: 0 | C16: 0 | D16: 0 | E16: 0 | F16: 456.5 | G16: 0 | H16: 0 | I16: 0 | J16: 0 | K16: 0 | L16: 0 | M16: 0 | N16: =SUM(B16:M16) -> 456.5
A17: TOTAL | B17: =SUM(B3:B16) -> 0 | C17: =SUM(C3:C16) -> 0 | D17: =SUM(D3:D16) -> 0 | E17: =SUM(E3:E16) -> 0 | F17: =SUM(F3:F16) -> 2375 | G17: =SUM(G3:G16) -> 0 | H17: =SUM(H3:H16) -> 0 | I17: =SUM(I3:I16) -> 0 | ... M17: =SUM(M3:M16) -> 0
A18: Jornal mes | B18: 0 | C18: 0 | D18: 0 | E18: 0 | F18: 2375 | G18: 0 | H18: 0 | I18: 0 | J18: 0 | K18: 0 | L18: 0 | M18: 0
